[2025-05-03T02:09:21.911+0000] {local_task_job_runner.py:123} INFO - ::group::Pre task execution logs
[2025-05-03T02:09:21.950+0000] {taskinstance.py:2612} INFO - Dependencies all met for dep_context=non-requeueable deps ti=<TaskInstance: BuildELT_dbt.dbt_snapshot manual__2025-05-03T02:08:36.186260+00:00 [queued]>
[2025-05-03T02:09:21.970+0000] {taskinstance.py:2612} INFO - Dependencies all met for dep_context=requeueable deps ti=<TaskInstance: BuildELT_dbt.dbt_snapshot manual__2025-05-03T02:08:36.186260+00:00 [queued]>
[2025-05-03T02:09:21.971+0000] {taskinstance.py:2865} INFO - Starting attempt 1 of 1
[2025-05-03T02:09:22.012+0000] {taskinstance.py:2888} INFO - Executing <Task(BashOperator): dbt_snapshot> on 2025-05-03 02:08:36.186260+00:00
[2025-05-03T02:09:22.031+0000] {standard_task_runner.py:104} INFO - Running: ['***', 'tasks', 'run', 'BuildELT_dbt', 'dbt_snapshot', 'manual__2025-05-03T02:08:36.186260+00:00', '--job-id', '9', '--raw', '--subdir', 'DAGS_FOLDER/build_elt_with_dbt.py', '--cfg-path', '/tmp/tmpd2ieoqdz']
[2025-05-03T02:09:22.040+0000] {standard_task_runner.py:105} INFO - Job 9: Subtask dbt_snapshot
[2025-05-03T02:09:22.044+0000] {logging_mixin.py:190} WARNING - /home/***/.local/lib/python3.12/site-packages/***/task/task_runner/standard_task_runner.py:70 DeprecationWarning: This process (pid=286) is multi-threaded, use of fork() may lead to deadlocks in the child.
[2025-05-03T02:09:22.048+0000] {standard_task_runner.py:72} INFO - Started process 287 to run task
[2025-05-03T02:09:22.176+0000] {task_command.py:467} INFO - Running <TaskInstance: BuildELT_dbt.dbt_snapshot manual__2025-05-03T02:08:36.186260+00:00 [running]> on host 2b57038454c6
[2025-05-03T02:09:22.521+0000] {taskinstance.py:3131} INFO - Exporting env vars: AIRFLOW_CTX_DAG_OWNER='***' AIRFLOW_CTX_DAG_ID='BuildELT_dbt' AIRFLOW_CTX_TASK_ID='dbt_snapshot' AIRFLOW_CTX_EXECUTION_DATE='2025-05-03T02:08:36.186260+00:00' AIRFLOW_CTX_TRY_NUMBER='1' AIRFLOW_CTX_DAG_RUN_ID='manual__2025-05-03T02:08:36.186260+00:00'
[2025-05-03T02:09:22.523+0000] {taskinstance.py:731} INFO - ::endgroup::
[2025-05-03T02:09:22.569+0000] {subprocess.py:63} INFO - Tmp dir root location: /tmp
[2025-05-03T02:09:22.576+0000] {subprocess.py:75} INFO - Running command: ['/usr/bin/bash', '-c', '/home/***/.local/bin/dbt snapshot --profiles-dir /opt/***/final_project_dbt --project-dir /opt/***/final_project_dbt']
[2025-05-03T02:09:22.598+0000] {subprocess.py:86} INFO - Output:
[2025-05-03T02:09:28.850+0000] {subprocess.py:93} INFO - [0m02:09:28  Running with dbt=1.9.4
[2025-05-03T02:09:31.338+0000] {subprocess.py:93} INFO - [0m02:09:31  Registered adapter: snowflake=1.9.4
[2025-05-03T02:09:32.369+0000] {subprocess.py:93} INFO - [0m02:09:32  Found 8 models, 2 snapshots, 5 data tests, 3 sources, 476 macros
[2025-05-03T02:09:32.382+0000] {subprocess.py:93} INFO - [0m02:09:32
[2025-05-03T02:09:32.384+0000] {subprocess.py:93} INFO - [0m02:09:32  Concurrency: 1 threads (target='dev')
[2025-05-03T02:09:32.386+0000] {subprocess.py:93} INFO - [0m02:09:32
[2025-05-03T02:09:34.950+0000] {subprocess.py:93} INFO - [0m02:09:34  1 of 2 START snapshot snapshot.dashboard_overview_snapshot ..................... [RUN]
[2025-05-03T02:09:39.425+0000] {subprocess.py:93} INFO - [0m02:09:39  1 of 2 OK snapshotted snapshot.dashboard_overview_snapshot ..................... [[32mSUCCESS 0[0m in 4.47s]
[2025-05-03T02:09:39.432+0000] {subprocess.py:93} INFO - [0m02:09:39  2 of 2 START snapshot snapshot.player_ranking_history_snapshot ................. [RUN]
[2025-05-03T02:39:19.459+0000] {subprocess.py:93} INFO - [0m02:39:19  2 of 2 ERROR snapshotting snapshot.player_ranking_history_snapshot ............. [[31mERROR[0m in 1779.99s]
[2025-05-03T02:39:19.650+0000] {subprocess.py:93} INFO - [0m02:39:19
[2025-05-03T02:39:19.652+0000] {subprocess.py:93} INFO - [0m02:39:19  Finished running 2 snapshots in 0 hours 29 minutes and 47.26 seconds (1787.26s).
[2025-05-03T02:39:19.794+0000] {subprocess.py:93} INFO - [0m02:39:19
[2025-05-03T02:39:19.795+0000] {subprocess.py:93} INFO - [0m02:39:19  [31mCompleted with 1 error, 0 partial successes, and 0 warnings:[0m
[2025-05-03T02:39:19.796+0000] {subprocess.py:93} INFO - [0m02:39:19
[2025-05-03T02:39:19.797+0000] {subprocess.py:93} INFO - [0m02:39:19    Database Error in snapshot player_ranking_history_snapshot (snapshots/player_ranking_history_snapshot.sql)
[2025-05-03T02:39:19.797+0000] {subprocess.py:93} INFO -   100090 (42P18): Duplicate row detected during DML action
[2025-05-03T02:39:19.797+0000] {subprocess.py:93} INFO -   Row Values: [redacted]
[2025-05-03T02:39:19.798+0000] {subprocess.py:93} INFO -   compiled code at target/run/final_project_dbt/snapshots/player_ranking_history_snapshot.sql
[2025-05-03T02:39:19.799+0000] {subprocess.py:93} INFO - [0m02:39:19
[2025-05-03T02:39:19.799+0000] {subprocess.py:93} INFO - [0m02:39:19  Done. PASS=1 WARN=0 ERROR=1 SKIP=0 TOTAL=2
[2025-05-03T02:39:21.104+0000] {subprocess.py:97} INFO - Command exited with return code 1
[2025-05-03T02:39:21.201+0000] {taskinstance.py:3310} ERROR - Task failed with exception
Traceback (most recent call last):
  File "/home/airflow/.local/lib/python3.12/site-packages/airflow/models/taskinstance.py", line 767, in _execute_task
    result = _execute_callable(context=context, **execute_callable_kwargs)
             ^^^^^^^^^^^^^^^^^^^^^^^^^^^^^^^^^^^^^^^^^^^^^^^^^^^^^^^^^^^^^
  File "/home/airflow/.local/lib/python3.12/site-packages/airflow/models/taskinstance.py", line 733, in _execute_callable
    return ExecutionCallableRunner(
           ^^^^^^^^^^^^^^^^^^^^^^^^
  File "/home/airflow/.local/lib/python3.12/site-packages/airflow/utils/operator_helpers.py", line 252, in run
    return self.func(*args, **kwargs)
           ^^^^^^^^^^^^^^^^^^^^^^^^^^
  File "/home/airflow/.local/lib/python3.12/site-packages/airflow/models/baseoperator.py", line 406, in wrapper
    return func(self, *args, **kwargs)
           ^^^^^^^^^^^^^^^^^^^^^^^^^^^
  File "/home/airflow/.local/lib/python3.12/site-packages/airflow/operators/bash.py", line 249, in execute
    raise AirflowException(
airflow.exceptions.AirflowException: Bash command failed. The command returned a non-zero exit code 1.
[2025-05-03T02:39:21.233+0000] {taskinstance.py:1225} INFO - Marking task as FAILED. dag_id=BuildELT_dbt, task_id=dbt_snapshot, run_id=manual__2025-05-03T02:08:36.186260+00:00, execution_date=20250503T020836, start_date=20250503T020921, end_date=20250503T023921
[2025-05-03T02:39:21.282+0000] {taskinstance.py:340} INFO - ::group::Post task execution logs
[2025-05-03T02:39:21.288+0000] {standard_task_runner.py:124} ERROR - Failed to execute job 9 for task dbt_snapshot (Bash command failed. The command returned a non-zero exit code 1.; 287)
Traceback (most recent call last):
  File "/home/airflow/.local/lib/python3.12/site-packages/airflow/task/task_runner/standard_task_runner.py", line 117, in _start_by_fork
    ret = args.func(args, dag=self.dag)
          ^^^^^^^^^^^^^^^^^^^^^^^^^^^^^
  File "/home/airflow/.local/lib/python3.12/site-packages/airflow/cli/cli_config.py", line 49, in command
    return func(*args, **kwargs)
           ^^^^^^^^^^^^^^^^^^^^^
  File "/home/airflow/.local/lib/python3.12/site-packages/airflow/utils/cli.py", line 115, in wrapper
    return f(*args, **kwargs)
           ^^^^^^^^^^^^^^^^^^
  File "/home/airflow/.local/lib/python3.12/site-packages/airflow/cli/commands/task_command.py", line 483, in task_run
    task_return_code = _run_task_by_selected_method(args, _dag, ti)
                       ^^^^^^^^^^^^^^^^^^^^^^^^^^^^^^^^^^^^^^^^^^^^
  File "/home/airflow/.local/lib/python3.12/site-packages/airflow/cli/commands/task_command.py", line 256, in _run_task_by_selected_method
    return _run_raw_task(args, ti)
           ^^^^^^^^^^^^^^^^^^^^^^^
  File "/home/airflow/.local/lib/python3.12/site-packages/airflow/cli/commands/task_command.py", line 341, in _run_raw_task
    return ti._run_raw_task(
           ^^^^^^^^^^^^^^^^^
  File "/home/airflow/.local/lib/python3.12/site-packages/airflow/utils/session.py", line 97, in wrapper
    return func(*args, session=session, **kwargs)
           ^^^^^^^^^^^^^^^^^^^^^^^^^^^^^^^^^^^^^^
  File "/home/airflow/.local/lib/python3.12/site-packages/airflow/models/taskinstance.py", line 3004, in _run_raw_task
    return _run_raw_task(
           ^^^^^^^^^^^^^^
  File "/home/airflow/.local/lib/python3.12/site-packages/airflow/models/taskinstance.py", line 273, in _run_raw_task
    TaskInstance._execute_task_with_callbacks(
  File "/home/airflow/.local/lib/python3.12/site-packages/airflow/models/taskinstance.py", line 3158, in _execute_task_with_callbacks
    result = self._execute_task(context, task_orig)
             ^^^^^^^^^^^^^^^^^^^^^^^^^^^^^^^^^^^^^^
  File "/home/airflow/.local/lib/python3.12/site-packages/airflow/models/taskinstance.py", line 3182, in _execute_task
    return _execute_task(self, context, task_orig)
           ^^^^^^^^^^^^^^^^^^^^^^^^^^^^^^^^^^^^^^^
  File "/home/airflow/.local/lib/python3.12/site-packages/airflow/models/taskinstance.py", line 767, in _execute_task
    result = _execute_callable(context=context, **execute_callable_kwargs)
             ^^^^^^^^^^^^^^^^^^^^^^^^^^^^^^^^^^^^^^^^^^^^^^^^^^^^^^^^^^^^^
  File "/home/airflow/.local/lib/python3.12/site-packages/airflow/models/taskinstance.py", line 733, in _execute_callable
    return ExecutionCallableRunner(
           ^^^^^^^^^^^^^^^^^^^^^^^^
  File "/home/airflow/.local/lib/python3.12/site-packages/airflow/utils/operator_helpers.py", line 252, in run
    return self.func(*args, **kwargs)
           ^^^^^^^^^^^^^^^^^^^^^^^^^^
  File "/home/airflow/.local/lib/python3.12/site-packages/airflow/models/baseoperator.py", line 406, in wrapper
    return func(self, *args, **kwargs)
           ^^^^^^^^^^^^^^^^^^^^^^^^^^^
  File "/home/airflow/.local/lib/python3.12/site-packages/airflow/operators/bash.py", line 249, in execute
    raise AirflowException(
airflow.exceptions.AirflowException: Bash command failed. The command returned a non-zero exit code 1.
[2025-05-03T02:39:21.334+0000] {local_task_job_runner.py:266} INFO - Task exited with return code 1
[2025-05-03T02:39:21.388+0000] {taskinstance.py:3900} INFO - 0 downstream tasks scheduled from follow-on schedule check
[2025-05-03T02:39:21.390+0000] {local_task_job_runner.py:245} INFO - ::endgroup::
